<?xml version="1.0"?>
<robot name="aut_exca" xmlns:xacro="http://ros.org/wiki/xacro">
  
<!-- Body Part -->
  <link name="base_footprint"/>

  <joint name="swing_joint" type="revolute">
    <axis xyz="0 0 1"/>
    <limit effort="1000.0" lower="0.0" upper="6.28318" velocity="0.5"/>
    <origin rpy="0 0 0" xyz="0.0 0.0 0.155"/>
    <parent link="base_footprint"/>
    <child link="swing_frame"/>
  </joint>

  <link name="swing_frame"/>

  <joint name="boom_joint" type="revolute">
    <axis xyz="0 0 1"/>
    <limit effort="1000.0" lower="0.0" upper="6.28318" velocity="0.5"/>
    <origin rpy="1.5708 0 -1.5708" xyz="0.05 0.0 0.0"/>
    <parent link="swing_frame"/>
    <child link="boom_frame"/>
  </joint>

  <link name="boom_frame"/>

  <joint name="arm_joint" type="revolute">
    <axis xyz="0 0 1"/>
    <limit effort="1000.0" lower="0.0" upper="6.28318" velocity="0.5"/>
    <origin rpy="0 0 0" xyz="-0.21 0.39 0.0"/>
    <parent link="boom_frame"/>
    <child link="arm_frame"/>
  </joint>

  <link name="arm_frame"/>

  <joint name="bucket_joint" type="revolute">
    <axis xyz="0 0 1"/>
    <limit effort="1000.0" lower="0.0" upper="6.28318" velocity="0.5"/>
    <origin rpy="0 0 0" xyz="-0.19 0.185 0.0"/>
    <parent link="arm_frame"/>
    <child link="bucket_frame"/>
  </joint>

  <link name="bucket_frame"/>

  <joint name="tip_joint" type="fixed">
      <origin rpy="0 0.0 0.0" xyz="-0.05 0.15 0"/>
      <parent link="bucket_frame"/>
      <child link="bucket_tip"/>
  </joint>

  <link name="bucket_tip"/>
    
    
</robot>